#VRML_SIM R2023b utf8

EXTERNPROTO "https://raw.githubusercontent.com/cyberbotics/webots/R2023a/projects/objects/backgrounds/protos/TexturedBackground.proto"
EXTERNPROTO "https://raw.githubusercontent.com/cyberbotics/webots/R2023a/projects/objects/backgrounds/protos/TexturedBackgroundLight.proto"
EXTERNPROTO "https://raw.githubusercontent.com/cyberbotics/webots/R2023a/projects/objects/road/protos/StraightRoadSegment.proto"
EXTERNPROTO "https://raw.githubusercontent.com/cyberbotics/webots/R2023a/projects/objects/floors/protos/Floor.proto"
EXTERNPROTO "https://raw.githubusercontent.com/cyberbotics/webots/R2023a/projects/appearances/protos/Grass.proto"
EXTERNPROTO "https://raw.githubusercontent.com/cyberbotics/webots/R2023a/projects/humans/pedestrian/protos/Pedestrian.proto"
EXTERNPROTO "https://raw.githubusercontent.com/cyberbotics/webots/R2023a/projects/objects/buildings/protos/Warehouse.proto"
EXTERNPROTO "https://raw.githubusercontent.com/cyberbotics/webots/R2023a/projects/objects/advertising_board/protos/AdvertisingBoard.proto"
EXTERNPROTO "https://raw.githubusercontent.com/cyberbotics/webots/R2023a/projects/objects/tables/protos/Table.proto"
EXTERNPROTO "https://raw.githubusercontent.com/cyberbotics/webots/R2023b/projects/vehicles/protos/tesla/TeslaModel3Simple.proto"

WorldInfo {
  title "Iris Ardupilot"
  basicTimeStep 1
  FPS 30
}
Viewpoint {
  orientation 0.030677513983748208 -0.9244525869742078 -0.38006092218547216 5.784080923808408
  position -32.62226053115998 -0.00533772054032533 9.007492329577865
  followSmoothness 0.01
}
TexturedBackground {
}
TexturedBackgroundLight {
}
Floor {
  size 300 100
  appearance Grass {
  }
}
StraightRoadSegment {
  translation -15 0.3 0.02
  rotation 0 0 1 0.105
  width 16.5
  rightBorder FALSE
  leftBorder FALSE
  length 140
}
Warehouse {
  translation 22.0473 -12.6792 0
  rotation 0 0 1 1.671
  name "warehouse_1"
}
Warehouse {
  translation 61.8844 -8.67468 0
  rotation 0 0 1 1.671
  name "warehouse_2"
}
Pedestrian {
  name "pedestrian_1"
  controllerArgs [
    "--speed=0.5"
    "--trajectory= 2 1, 3 -7, 18 6, 26 15, 4 12, -2 1, -1 -9, 3 -2"
  ]
  rightLegAngle 0.22227272727272973
  rightLowerLegAngle 0.11931818181818472
  rightFootAngle 0.35795454545455413
  leftLegAngle -1.097159090909097
  leftLowerLegAngle 1.6907954545454573
  leftFootAngle -0.04931818181818472
  rightArmAngle -0.2817045454545564
  rightLowerArmAngle -0.5386363636363694
  rightHandAngle -0.23818181818181983
  leftArmAngle 0.47215909090910596
  leftLowerArmAngle -0.6202272727272838
  leftHandAngle 0.10227272727272975
  headAngle 0.013295454545452685
}
Pedestrian {
  translation 9.22306076215406 -1.6251953936221084 1.3322727272727206
  rotation 0 0 1 0.9048270894157867
  name "pedestrian_2"
  controllerArgs [
    "--speed=1.5"
    "--trajectory= 3 2, 5 -7, 16 7, 26 20, 4 12, -2 1, -1 -9, 3 -2"
  ]
  shirtColor 0.901961 0.380392 0
  pantsColor 0.6 0.756863 0.945098
  skinColor 0.753338 0.553536 0.291295
  rightLegAngle -1.0114772727272248
  rightLowerLegAngle 1.6523863636363423
  rightFootAngle -0.007954545454522302
  leftLegAngle 0.18681818181816195
  leftLowerLegAngle 0.07795454545452231
  leftFootAngle 0.17818181818176526
  rightArmAngle 0.256477272727152
  rightLowerArmAngle -0.4606818181817288
  rightHandAngle 0.06681818181816197
  leftArmAngle -0.1251136363635487
  leftLowerArmAngle -0.4559090909090446
  leftHandAngle -0.21454545454544133
  headAngle 0.03988636363637852
}
Table {
  translation 0 0.92 0
}
AdvertisingBoard {
  translation 13 19 0
  rotation 0 0 1 -1.469
  frontTexture [
    "../images/air.jpg"
  ]
  backTexture [
    "../images/air.jpg"
  ]
  displayWidth 9
  displayHeight 9
  poleNumber 1
  poleType "H-shape"
  poleHeight 13
}
Robot {
  translation -19.3913985179331 2.837625589181105 0.07498160624999997
  rotation -5.895069780946123e-19 1.0531893651725218e-19 0.9999999999999999 -2.877465307179586
  children [
    DEF CAMERA_YAW HingeJoint {
      jointParameters HingeJointParameters {
        position 8.137394277669185e-16
        axis 0 0 1
        anchor 0.0412774 -0.00469654 -0.00405862
      }
      device [
        RotationalMotor {
          name "camera yaw"
          minPosition -1.7
          maxPosition 1.7
        }
        PositionSensor {
          name "camera yaw sensor"
        }
      ]
      endPoint Solid {
        translation 0.08127700000000003 -0.004696540261830168 -0.014058599999999699
        children [
          Shape {
            appearance DEF METAL_APPEARANCE PBRAppearance {
              roughness 0.5
            }
            geometry Mesh {
              url [
                "/home/arthur/Desktop/simulation/webots/protos/meshes/camera_yaw.obj"
              ]
            }
          }
          DEF CAMERA_PITCH HingeJoint {
            jointParameters HingeJointParameters {
              position 0.6108651353843648
              axis 0 1 0
              anchor 0.000625212 -0.00530346 -0.0207448
            }
            device [
              RotationalMotor {
                name "camera pitch"
                minPosition -0.5
                maxPosition 1.7
              }
              PositionSensor {
                name "camera pitch sensor"
              }
            ]
            endPoint Solid {
              translation 0.0006252119999998982 -0.0053034599999999266 -0.020744800000000074
              rotation 0 1 0 0.6108651353843652
              children [
                Shape {
                  appearance USE METAL_APPEARANCE
                  geometry Mesh {
                    url [
                      "/home/arthur/Desktop/simulation/webots/protos/meshes/camera_pitch.obj"
                    ]
                  }
                }
                DEF CAMERA_ROLL HingeJoint {
                  jointParameters HingeJointParameters {
                    position -5.0640613323048616e-21
                    anchor 0.00754686 0.0160388 -0.00586401
                  }
                  device [
                    RotationalMotor {
                      name "camera roll"
                      minPosition -0.5
                      maxPosition 0.5
                    }
                    PositionSensor {
                      name "camera roll sensor"
                    }
                  ]
                  endPoint Solid {
                    translation 0.007546860000000044 0.016038800000000242 -0.005864010000000031
                    rotation 1 0 0 0
                    children [
                      Shape {
                        appearance USE METAL_APPEARANCE
                        geometry Mesh {
                          url [
                            "/home/arthur/Desktop/simulation/webots/protos/meshes/camera_chassis.obj"
                          ]
                        }
                      }
                      Shape {
                        appearance DEF GLASS PBRAppearance {
                          baseColor 0.523146 0.8 0.627785
                          transparency 0.9
                          roughness 0.5
                          metalness 0
                        }
                        geometry Mesh {
                          url [
                            "/home/arthur/Desktop/simulation/webots/protos/meshes/camera_lens.obj"
                          ]
                        }
                      }
                      DEF GIMBAL_SLOT Pose {
                        children [
                          RangeFinder {
                            name "rangefinder"
                            fieldOfView 0.01
                            minRange 1
                            maxRange 1000
                          }
                          RangeFinder {
                            name "depth_camera"
                            fieldOfView 0.785
                            width 320
                            height 240
                            minRange 0.1
                            maxRange 20
                          }
                          Camera {
                            name "color_camera"
                            fieldOfView 0.785
                            width 640
                            height 480
                          }
                        ]
                      }
                    ]
                    name "camera roll"
                    boundingObject Pose {
                      translation -0.00915058 -1.86265e-08 -0.000983764
                      children [
                        Box {
                          size 0.0236511 0.0205141 0.0225186
                        }
                      ]
                    }
                  }
                }
              ]
              name "camera pitch"
              boundingObject Pose {
                translation -0.00248347 0.00776876 0.00183829
                children [
                  Box {
                    size 0.0239878 0.0349393 0.0314891
                  }
                ]
              }
            }
          }
        ]
        name "camera yaw"
        boundingObject Pose {
          translation -1.86265e-09 -0.00304481 -0.0140589
          children [
            Box {
              size 0.0208626 0.0260333 0.0307844
            }
          ]
        }
      }
    }
    DEF IRIS_MESH Shape {
      appearance PBRAppearance {
        baseColor 0.05 0.05 0.05
        roughness 1
        metalness 0.2
      }
      geometry Mesh {
        url [
          "/home/arthur/Desktop/simulation/webots/protos/meshes/iris.dae"
        ]
      }
      castShadows FALSE
    }
    Propeller {
      shaftAxis 0 0 1
      centerOfThrust 0.13 -0.22 0.023
      thrustConstants 0.0012 0
      torqueConstants 0.0005 0
      device RotationalMotor {
        name "m1_motor"
        maxVelocity 100
        maxTorque 30
      }
      slowHelix Solid {
        translation 0.13 -0.22 0.023
        rotation 0 0 -1 2.1009498179827926
        children [
          Shape {
            appearance DEF PROP_BLUE PBRAppearance {
              baseColor 0 0 0.75
              metalness 0.3
            }
            geometry DEF CCW_PROP Mesh {
              url [
                "/home/arthur/Desktop/simulation/webots/protos/meshes/iris_prop_ccw.dae"
              ]
            }
          }
        ]
      }
    }
    Propeller {
      shaftAxis 0 0 1
      centerOfThrust -0.13 0.2 0.023
      thrustConstants 0.0012 0
      torqueConstants 0.0005 0
      device RotationalMotor {
        name "m2_motor"
        maxVelocity 100
        maxTorque 30
      }
      slowHelix Solid {
        translation -0.13 0.2 0.023
        rotation 0 0 -1 1.9199011801010344
        children [
          Shape {
            appearance DEF PROP_BLACK PBRAppearance {
              baseColor 0 0 0
              metalness 0.3
            }
            geometry USE CCW_PROP
          }
        ]
      }
    }
    Propeller {
      shaftAxis 0 0 1
      centerOfThrust 0.13 0.22 0.023
      thrustConstants -0.0012 0
      torqueConstants 0.0005 0
      device RotationalMotor {
        name "m3_motor"
        maxVelocity 100
        maxTorque 30
        multiplier -1
      }
      slowHelix Solid {
        translation 0.13 0.22 0.023
        rotation 0 0 1 1.3096900936597666
        children [
          Shape {
            appearance USE PROP_BLUE
            geometry DEF CW_PROP Mesh {
              url [
                "/home/arthur/Desktop/simulation/webots/protos/meshes/iris_prop_cw.dae"
              ]
            }
          }
        ]
      }
    }
    Propeller {
      shaftAxis 0 0 1
      centerOfThrust -0.13 -0.2 0.023
      thrustConstants -0.0012 0
      torqueConstants 0.0005 0
      device RotationalMotor {
        name "m4_motor"
        maxVelocity 100
        maxTorque 30
        multiplier -1
      }
      slowHelix Solid {
        translation -0.13 -0.2 0.023
        rotation 0 0 0.9999999999999999 1.9631340497598568
        children [
          Shape {
            appearance USE PROP_BLACK
            geometry USE CW_PROP
          }
        ]
      }
    }
    Accelerometer {
    }
    GPS {
    }
    Gyro {
    }
    InertialUnit {
    }
  ]
  name "Iris"
  boundingObject Box {
    size 0.47 0.47 0.15
  }
  physics Physics {
    density -1
    mass 1.5
    centerOfMass [
      0 0 0
    ]
    inertiaMatrix [
      0.029125 0.029125 0.055225
      0 0 0
    ]
  }
  controller "ardupilot_vehicle_controller"
  linearVelocity -1.683021589947556e-19 -8.927835802902151e-19 5.1005126048645866e-15
  angularVelocity -1.1435773644196614e-17 7.623849096143315e-18 -1.8725475811876278e-19
}
TeslaModel3Simple {
  translation 23.3064 8.11486 0.4
  rotation 0 0 1 2.87979
}
