#VRML_SIM R2023b utf8

EXTERNPROTO "https://raw.githubusercontent.com/cyberbotics/webots/R2023a/projects/objects/backgrounds/protos/TexturedBackground.proto"
EXTERNPROTO "https://raw.githubusercontent.com/cyberbotics/webots/R2023a/projects/objects/backgrounds/protos/TexturedBackgroundLight.proto"
EXTERNPROTO "https://raw.githubusercontent.com/cyberbotics/webots/R2023a/projects/objects/road/protos/StraightRoadSegment.proto"
EXTERNPROTO "https://raw.githubusercontent.com/cyberbotics/webots/R2023a/projects/objects/floors/protos/Floor.proto"
EXTERNPROTO "https://raw.githubusercontent.com/cyberbotics/webots/R2023a/projects/appearances/protos/Grass.proto"
EXTERNPROTO "https://raw.githubusercontent.com/cyberbotics/webots/R2023a/projects/humans/pedestrian/protos/Pedestrian.proto"
EXTERNPROTO "https://raw.githubusercontent.com/cyberbotics/webots/R2023a/projects/objects/buildings/protos/Warehouse.proto"
EXTERNPROTO "https://raw.githubusercontent.com/cyberbotics/webots/R2023a/projects/objects/advertising_board/protos/AdvertisingBoard.proto"
EXTERNPROTO "https://raw.githubusercontent.com/cyberbotics/webots/R2023a/projects/objects/tables/protos/Table.proto"


WorldInfo {
  title "Iris Ardupilot"
  basicTimeStep 1
  FPS 30
}
Viewpoint {
  orientation -0.15488872288352273 -0.8697642574712708 0.4685292092804464 5.885033079753205
  position -7.324108725779209 2.6950930318612234 3.654984306983507
  followSmoothness 0.01
}
TexturedBackground {
}
TexturedBackgroundLight {
}
Floor {
  size 300 100
  appearance Grass {
  }
}
StraightRoadSegment {
  translation -15 0.3 0.02
  rotation 0 0 1 0.105
  width 16.5
  rightBorder FALSE
  leftBorder FALSE
  length 140
}
Warehouse {
  translation 22.0473 -12.6792 0
  rotation 0 0 1 1.671
}
Warehouse {
  translation 61.8844 -8.67468 0
  rotation 0 0 1 1.671
  name "warehouse(1)"
}
Pedestrian {
  translation 5.675616554308785 1.8243834456912147 1.274818181818182
  rotation 0 0 1 -0.7853981633974483
  controllerArgs [
    "--speed=0.5"
    "--trajectory= 2 1, 3 -7, 18 6, 26 15, 4 12, -2 1, -1 -9, 3 -2"
  ]
}
Table {
  translation 0 0.92 0
}
AdvertisingBoard {
  translation 13 19 0
  rotation 0 0 1 -1.469
  frontTexture [
    "../images/air.jpg"
  ]
  backTexture [
    "../images/air.jpg"
  ]
  displayWidth 9
  displayHeight 9
  poleNumber 1
  poleType "H-shape"
  poleHeight 13
}
Robot {
  translation 2.287269709546407 0.21189346720593275 0.05498160624999999
  rotation 2.822609118148114e-21 -1.9325817409233463e-20 -1 0.44561700000000004
  children [
    DEF CAMERA_YAW HingeJoint {
      jointParameters HingeJointParameters {
        axis 0 0 1
        anchor 0.0412774 -0.00469654 -0.00405862
      }
      device [
        RotationalMotor {
          name "camera yaw"
          minPosition -1.7
          maxPosition 1.7
        }
        PositionSensor {
          name "camera yaw sensor"
        }
      ]
      endPoint Solid {
        translation 0.08127700000000003 -0.004696540261830201 -0.014058599999999699
        children [
          Shape {
            appearance DEF METAL_APPEARANCE PBRAppearance {
              roughness 0.5
            }
            geometry Mesh {
              url [
                "/home/arthur/Desktop/simulation/webots/protos/meshes/camera_yaw.obj"
              ]
            }
          }
          DEF CAMERA_PITCH HingeJoint {
            jointParameters HingeJointParameters {
              position -0.082
              axis 0 1 0
              anchor 0.000625212 -0.00530346 -0.0207448
            }
            device [
              RotationalMotor {
                name "camera pitch"
                minPosition -0.5
                maxPosition 1.7
              }
              PositionSensor {
                name "camera pitch sensor"
              }
            ]
            endPoint Solid {
              translation 0.0006252119999999681 -0.0053034599999999266 -0.020744800000000122
              rotation 0 -1 0 0.08199999999999856
              children [
                Shape {
                  appearance USE METAL_APPEARANCE
                  geometry Mesh {
                    url [
                      "/home/arthur/Desktop/simulation/webots/protos/meshes/camera_pitch.obj"
                    ]
                  }
                }
                DEF CAMERA_ROLL HingeJoint {
                  jointParameters HingeJointParameters {
                    position 0.01
                    anchor 0.00754686 0.0160388 -0.00586401
                  }
                  device [
                    RotationalMotor {
                      name "camera roll"
                      minPosition -0.5
                      maxPosition 0.5
                    }
                    PositionSensor {
                      name "camera roll sensor"
                    }
                  ]
                  endPoint Solid {
                    translation 0.007546860000000044 0.016038800000000242 -0.005864010000000028
                    rotation 1 0 0 0.01000000000000101
                    children [
                      Shape {
                        appearance USE METAL_APPEARANCE
                        geometry Mesh {
                          url [
                            "/home/arthur/Desktop/simulation/webots/protos/meshes/camera_chassis.obj"
                          ]
                        }
                      }
                      Shape {
                        appearance DEF GLASS PBRAppearance {
                          baseColor 0.523146 0.8 0.627785
                          transparency 0.9
                          roughness 0.5
                          metalness 0
                        }
                        geometry Mesh {
                          url [
                            "/home/arthur/Desktop/simulation/webots/protos/meshes/camera_lens.obj"
                          ]
                        }
                      }
                      DEF GIMBAL_SLOT Pose {
                        children [
                          RangeFinder {
                            name "rangefinder"
                            fieldOfView 0.01
                            width 64
                            height 64
                            minRange 1
                            maxRange 1000
                          }
                          RangeFinder {
                            name "depth_camera"
                            fieldOfView 0.785
                            width 320
                            height 240
                            minRange 0.1
                            maxRange 20
                          }
                          Camera {
                            name "color_camera"
                            fieldOfView 0.785
                            width 640
                            height 480
                          }
                        ]
                      }
                    ]
                    name "camera roll"
                    boundingObject Pose {
                      translation -0.00915058 -1.86265e-08 -0.000983764
                      children [
                        Box {
                          size 0.0236511 0.0205141 0.0225186
                        }
                      ]
                    }
                  }
                }
              ]
              name "camera pitch"
              boundingObject Pose {
                translation -0.00248347 0.00776876 0.00183829
                children [
                  Box {
                    size 0.0239878 0.0349393 0.0314891
                  }
                ]
              }
            }
          }
        ]
        name "camera yaw"
        boundingObject Pose {
          translation -1.86265e-09 -0.00304481 -0.0140589
          children [
            Box {
              size 0.0208626 0.0260333 0.0307844
            }
          ]
        }
      }
    }
    DEF IRIS_MESH Shape {
      appearance PBRAppearance {
        baseColor 0.05 0.05 0.05
        roughness 1
        metalness 0.2
      }
      geometry Mesh {
        url [
          "/home/arthur/Desktop/simulation/webots/protos/meshes/iris.dae"
        ]
      }
      castShadows FALSE
    }
    Propeller {
      shaftAxis 0 0 1
      centerOfThrust 0.13 -0.22 0.023
      thrustConstants 0.0012 0
      torqueConstants 0.0005 0
      device RotationalMotor {
        name "m1_motor"
        maxVelocity 100
        maxTorque 30
      }
      slowHelix Solid {
        translation 0.13 -0.22 0.023
        rotation 0 0 1 4.886831309026521
        children [
          Shape {
            appearance DEF PROP_BLUE PBRAppearance {
              baseColor 0 0 0.75
              metalness 0.3
            }
            geometry DEF CCW_PROP Mesh {
              url [
                "/home/arthur/Desktop/simulation/webots/protos/meshes/iris_prop_ccw.dae"
              ]
            }
          }
        ]
      }
    }
    Propeller {
      shaftAxis 0 0 1
      centerOfThrust -0.13 0.2 0.023
      thrustConstants 0.0012 0
      torqueConstants 0.0005 0
      device RotationalMotor {
        name "m2_motor"
        maxVelocity 100
        maxTorque 30
      }
      slowHelix Solid {
        translation -0.13 0.2 0.023
        rotation 0 0 1 4.8658114879349075
        children [
          Shape {
            appearance DEF PROP_BLACK PBRAppearance {
              baseColor 0 0 0
              metalness 0.3
            }
            geometry USE CCW_PROP
          }
        ]
      }
    }
    Propeller {
      shaftAxis 0 0 1
      centerOfThrust 0.13 0.22 0.023
      thrustConstants -0.0012 0
      torqueConstants 0.0005 0
      device RotationalMotor {
        name "m3_motor"
        maxVelocity 100
        maxTorque 30
        multiplier -1
      }
      slowHelix Solid {
        translation 0.13 0.22 0.023
        rotation 0 0 -1 4.8340204920809535
        children [
          Shape {
            appearance USE PROP_BLUE
            geometry DEF CW_PROP Mesh {
              url [
                "/home/arthur/Desktop/simulation/webots/protos/meshes/iris_prop_cw.dae"
              ]
            }
          }
        ]
      }
    }
    Propeller {
      shaftAxis 0 0 1
      centerOfThrust -0.13 -0.2 0.023
      thrustConstants -0.0012 0
      torqueConstants 0.0005 0
      device RotationalMotor {
        name "m4_motor"
        maxVelocity 100
        maxTorque 30
        multiplier -1
      }
      slowHelix Solid {
        translation -0.13 -0.2 0.023
        rotation 0 0 -1 4.894446474265779
        children [
          Shape {
            appearance USE PROP_BLACK
            geometry USE CW_PROP
          }
        ]
      }
    }
    Accelerometer {
    }
    GPS {
    }
    Gyro {
    }
    InertialUnit {
    }
  ]
  name "Iris"
  boundingObject Box {
    size 0.47 0.47 0.15
  }
  physics Physics {
    density -1
    mass 1.5
    centerOfMass [
      0 0 0
    ]
    inertiaMatrix [
      0.029125 0.029125 0.055225
      0 0 0
    ]
  }
  controller "ardupilot_vehicle_controller"
  linearVelocity 7.602132869149125e-19 7.755548745148268e-20 2.394529019511662e-15
  angularVelocity 5.717886822101866e-18 3.8119245480692224e-18 1.8562931687736606e-19
}
